{
    "registryname":"orematic5000_mk3",
    "localizedname":"OreMatic 5000 Mk3",
    "color":"AAB4BA",
    "parts":[
       {
          "x":-1,
          "y":0,
          "z":0,
          "elements":[
             "modularmachinery:blockcasing@0"
          ]
       },
       {
          "x":2,
          "y":4,
          "z":2,
          "elements":[
             "modularmachinery:blockcasing@0"
          ]
       },
       {
          "x":1,
          "y":2,
          "z":1,
          "elements":[
             "xnet:netcable@1"
          ]
       },
       {
          "x":-2,
          "y":0,
          "z":0,
          "elements":[
             "modularmachinery:blockcasing@0"
          ]
       },
       {
          "x":2,
          "y":2,
          "z":1,
          "elements":[
             "chisel:technical@14"
          ]
       },
       {
          "x":1,
          "y":0,
          "z":0,
          "elements":[
             "modularmachinery:blockcasing@0"
          ]
       },
       {
          "x":2,
          "y":0,
          "z":0,
          "elements":[
             "modularmachinery:blockcasing@0"
          ]
       },
       {
          "x":-2,
          "y":0,
          "z":4,
          "elements":[
             "modularmachinery:blockcasing@0"
          ]
       },
       {
          "x":-1,
          "y":0,
          "z":4,
          "elements":[
             "modularmachinery:blockcasing@0"
          ]
       },
       {
          "x":0,
          "y":0,
          "z":4,
          "elements":[
             "modularmachinery:blockenergyinputhatch"
          ]
       },
       {
          "x":1,
          "y":0,
          "z":4,
          "elements":[
             "modularmachinery:blockcasing@0"
          ]
       },
       {
          "x":2,
          "y":0,
          "z":4,
          "elements":[
             "modularmachinery:blockcasing@0"
          ]
       },
       {
          "x":-2,
          "y":3,
          "z":1,
          "elements":[
             "chisel:technical@14"
          ]
       },
       {
          "x":-2,
          "y":1,
          "z":0,
          "elements":[
             "modularmachinery:blockcasing@0"
          ]
       },
       {
          "x":-1,
          "y":3,
          "z":1,
          "elements":[
             "xnet:netcable@1"
          ]
       },
       {
          "x":0,
          "y":3,
          "z":1,
          "elements":[
             "xnet:netcable@1"
          ]
       },
       {
          "x":-1,
          "y":1,
          "z":0,
          "elements":[
             "chisel:technical@14"
          ]
       },
       {
          "x":1,
          "y":3,
          "z":1,
          "elements":[
             "xnet:netcable@1"
          ]
       },
       {
          "x":0,
          "y":1,
          "z":0,
          "elements":[
             "appliedenergistics2:quartz_glass@0"
          ]
       },
       {
          "x":2,
          "y":3,
          "z":1,
          "elements":[
             "chisel:technical@14"
          ]
       },
       {
          "x":1,
          "y":1,
          "z":0,
          "elements":[
             "chisel:technical@14"
          ]
       },
       {
          "x":-2,
          "y":1,
          "z":4,
          "elements":[
             "modularmachinery:blockcasing@0"
          ]
       },
       {
          "x":2,
          "y":1,
          "z":0,
          "elements":[
             "modularmachinery:blockfluidinputhatch"
          ]
       },
       {
          "x":-1,
          "y":1,
          "z":4,
          "elements":[
             "chisel:technical@14"
          ]
       },
       {
          "x":0,
          "y":1,
          "z":4,
          "elements":[
             "appliedenergistics2:quartz_glass@0"
          ]
       },
       {
          "x":1,
          "y":1,
          "z":4,
          "elements":[
             "chisel:technical@14"
          ]
       },
       {
          "x":2,
          "y":1,
          "z":4,
          "elements":[
             "modularmachinery:blockfluidinputhatch"
          ]
       },
       {
          "x":-2,
          "y":4,
          "z":1,
          "elements":[
             "modularmachinery:blockcasing@0"
          ]
       },
       {
          "x":-2,
          "y":2,
          "z":0,
          "elements":[
             "modularmachinery:blockcasing@0"
          ]
       },
       {
          "x":-1,
          "y":4,
          "z":1,
          "elements":[
             "appliedenergistics2:quartz_glass@0"
          ]
       },
       {
          "x":0,
          "y":4,
          "z":1,
          "elements":[
             "appliedenergistics2:quartz_glass@0"
          ]
       },
       {
          "x":-1,
          "y":2,
          "z":0,
          "elements":[
             "chisel:technical@14"
          ]
       },
       {
          "x":1,
          "y":4,
          "z":1,
          "elements":[
             "appliedenergistics2:quartz_glass@0"
          ]
       },
       {
          "x":0,
          "y":2,
          "z":0,
          "elements":[
             "appliedenergistics2:quartz_glass@0"
          ]
       },
       {
          "x":2,
          "y":4,
          "z":1,
          "elements":[
             "modularmachinery:blockcasing@0"
          ]
       },
       {
          "x":1,
          "y":2,
          "z":0,
          "elements":[
             "chisel:technical@14"
          ]
       },
       {
          "x":-2,
          "y":2,
          "z":4,
          "elements":[
             "modularmachinery:blockcasing@0"
          ]
       },
       {
          "x":2,
          "y":2,
          "z":0,
          "elements":[
             "modularmachinery:blockfluidinputhatch"
          ]
       },
       {
          "x":-2,
          "y":0,
          "z":3,
          "elements":[
             "modularmachinery:blockcasing@0"
          ]
       },
       {
          "x":-1,
          "y":2,
          "z":4,
          "elements":[
             "chisel:technical@14"
          ]
       },
       {
          "x":0,
          "y":2,
          "z":4,
          "elements":[
             "appliedenergistics2:quartz_glass@0"
          ]
       },
       {
          "x":-1,
          "y":0,
          "z":3,
          "elements":[
             "modularmachinery:blockcasing@0"
          ]
       },
       {
          "x":0,
          "y":0,
          "z":3,
          "elements":[
             "modularmachinery:blockcasing@0"
          ]
       },
       {
          "x":1,
          "y":2,
          "z":4,
          "elements":[
             "chisel:technical@14"
          ]
       },
       {
          "x":2,
          "y":2,
          "z":4,
          "elements":[
             "modularmachinery:blockfluidinputhatch"
          ]
       },
       {
          "x":1,
          "y":0,
          "z":3,
          "elements":[
             "modularmachinery:blockcasing@0"
          ]
       },
       {
          "x":2,
          "y":0,
          "z":3,
          "elements":[
             "modularmachinery:blockcasing@0"
          ]
       },
       {
          "x":-2,
          "y":3,
          "z":0,
          "elements":[
             "modularmachinery:blockcasing@0"
          ]
       },
       {
          "x":-1,
          "y":3,
          "z":0,
          "elements":[
             "chisel:technical@14"
          ]
       },
       {
          "x":0,
          "y":3,
          "z":0,
          "elements":[
             "appliedenergistics2:quartz_glass@0"
          ]
       },
       {
          "x":1,
          "y":3,
          "z":0,
          "elements":[
             "chisel:technical@14"
          ]
       },
       {
          "x":-2,
          "y":3,
          "z":4,
          "elements":[
             "modularmachinery:blockcasing@0"
          ]
       },
       {
          "x":2,
          "y":3,
          "z":0,
          "elements":[
             "modularmachinery:blockfluidinputhatch"
          ]
       },
       {
          "x":-2,
          "y":1,
          "z":3,
          "elements":[
             "chisel:technical@14"
          ]
       },
       {
          "x":-1,
          "y":3,
          "z":4,
          "elements":[
             "chisel:technical@14"
          ]
       },
       {
          "x":0,
          "y":3,
          "z":4,
          "elements":[
             "appliedenergistics2:quartz_glass@0"
          ]
       },
       {
          "x":-1,
          "y":1,
          "z":3,
          "elements":[
             "xnet:netcable@1"
          ]
       },
       {
          "x":1,
          "y":3,
          "z":4,
          "elements":[
             "chisel:technical@14"
          ]
       },
       {
          "x":0,
          "y":1,
          "z":3,
          "nbt":{
             "id":"overloaded:infinite_barrel"
          },
          "elements":[
             "overloaded:infinite_barrel@0"
          ]
       },
       {
          "x":2,
          "y":3,
          "z":4,
          "elements":[
             "modularmachinery:blockfluidinputhatch"
          ]
       },
       {
          "x":1,
          "y":1,
          "z":3,
          "elements":[
             "xnet:netcable@1"
          ]
       },
       {
          "x":2,
          "y":1,
          "z":3,
          "elements":[
             "chisel:technical@14"
          ]
       },
       {
          "x":-2,
          "y":4,
          "z":0,
          "elements":[
             "modularmachinery:blockcasing@0"
          ]
       },
       {
          "x":-1,
          "y":4,
          "z":0,
          "elements":[
             "modularmachinery:blockcasing@0"
          ]
       },
       {
          "x":0,
          "y":4,
          "z":0,
          "elements":[
             "modularmachinery:blockcasing@0"
          ]
       },
       {
          "x":1,
          "y":4,
          "z":0,
          "elements":[
             "modularmachinery:blockcasing@0"
          ]
       },
       {
          "x":-2,
          "y":4,
          "z":4,
          "elements":[
             "modularmachinery:blockcasing@0"
          ]
       },
       {
          "x":2,
          "y":4,
          "z":0,
          "elements":[
             "modularmachinery:blockcasing@0"
          ]
       },
       {
          "x":-2,
          "y":2,
          "z":3,
          "elements":[
             "chisel:technical@14"
          ]
       },
       {
          "x":-1,
          "y":4,
          "z":4,
          "elements":[
             "modularmachinery:blockcasing@0"
          ]
       },
       {
          "x":0,
          "y":4,
          "z":4,
          "elements":[
             "modularmachinery:blockcasing@0"
          ]
       },
       {
          "x":-2,
          "y":0,
          "z":2,
          "elements":[
             "modularmachinery:blockoutputbus"
          ]
       },
       {
          "x":-1,
          "y":2,
          "z":3,
          "elements":[
             "xnet:netcable@1"
          ]
       },
       {
          "x":1,
          "y":4,
          "z":4,
          "elements":[
             "modularmachinery:blockcasing@0"
          ]
       },
       {
          "x":-1,
          "y":0,
          "z":2,
          "elements":[
             "modularmachinery:blockcasing@0"
          ]
       },
       {
          "x":0,
          "y":0,
          "z":2,
          "elements":[
             "modularmachinery:blockcasing@0"
          ]
       },
       {
          "x":2,
          "y":4,
          "z":4,
          "elements":[
             "modularmachinery:blockcasing@0"
          ]
       },
       {
          "x":1,
          "y":2,
          "z":3,
          "elements":[
             "xnet:netcable@1"
          ]
       },
       {
          "x":2,
          "y":2,
          "z":3,
          "elements":[
             "chisel:technical@14"
          ]
       },
       {
          "x":1,
          "y":0,
          "z":2,
          "elements":[
             "modularmachinery:blockcasing@0"
          ]
       },
       {
          "x":2,
          "y":0,
          "z":2,
          "elements":[
             "modularmachinery:blockinputbus"
          ]
       },
       {
          "x":-2,
          "y":3,
          "z":3,
          "elements":[
             "chisel:technical@14"
          ]
       },
       {
          "x":-2,
          "y":1,
          "z":2,
          "elements":[
             "appliedenergistics2:quartz_glass@0"
          ]
       },
       {
          "x":-1,
          "y":3,
          "z":3,
          "elements":[
             "xnet:netcable@1"
          ]
       },
       {
          "x":0,
          "y":3,
          "z":3,
          "elements":[
             "xnet:netcable@1"
          ]
       },
       {
          "x":-1,
          "y":1,
          "z":2,
          "elements":[
             "abyssalcraft:crystallizer"
          ]
       },
       {
          "x":1,
          "y":3,
          "z":3,
          "elements":[
             "xnet:netcable@1"
          ]
       },
       {
          "x":0,
          "y":1,
          "z":2,
          "elements":[
             "enderutilities:machine_0@0"
          ]
       },
       {
          "x":2,
          "y":3,
          "z":3,
          "elements":[
             "chisel:technical@14"
          ]
       },
       {
          "x":1,
          "y":1,
          "z":2,
          "elements":[
             "abyssalcraft:materializer"
          ]
       },
       {
          "x":2,
          "y":1,
          "z":2,
          "elements":[
             "appliedenergistics2:quartz_glass@0"
          ]
       },
       {
          "x":-2,
          "y":4,
          "z":3,
          "elements":[
             "modularmachinery:blockcasing@0"
          ]
       },
       {
          "x":-2,
          "y":2,
          "z":2,
          "elements":[
             "appliedenergistics2:quartz_glass@0"
          ]
       },
       {
          "x":-1,
          "y":4,
          "z":3,
          "elements":[
             "appliedenergistics2:quartz_glass@0"
          ]
       },
       {
          "x":0,
          "y":4,
          "z":3,
          "elements":[
             "appliedenergistics2:quartz_glass@0"
          ]
       },
       {
          "x":-2,
          "y":0,
          "z":1,
          "elements":[
             "modularmachinery:blockcasing@0"
          ]
       },
       {
          "x":1,
          "y":4,
          "z":3,
          "elements":[
             "appliedenergistics2:quartz_glass@0"
          ]
       },
       {
          "x":0,
          "y":2,
          "z":2,
          "elements":[
             "mysticalagriculture:ultimate_furnace"
          ]
       },
       {
          "x":-1,
          "y":0,
          "z":1,
          "elements":[
             "modularmachinery:blockcasing@0"
          ]
       },
       {
          "x":0,
          "y":0,
          "z":1,
          "elements":[
             "modularmachinery:blockcasing@0"
          ]
       },
       {
          "x":2,
          "y":4,
          "z":3,
          "elements":[
             "modularmachinery:blockcasing@0"
          ]
       },
       {
          "x":2,
          "y":2,
          "z":2,
          "elements":[
             "appliedenergistics2:quartz_glass@0"
          ]
       },
       {
          "x":1,
          "y":0,
          "z":1,
          "elements":[
             "modularmachinery:blockcasing@0"
          ]
       },
       {
          "x":2,
          "y":0,
          "z":1,
          "elements":[
             "modularmachinery:blockcasing@0"
          ]
       },
       {
          "x":-2,
          "y":3,
          "z":2,
          "elements":[
             "appliedenergistics2:quartz_glass@0"
          ]
       },
       {
          "x":-2,
          "y":1,
          "z":1,
          "elements":[
             "chisel:technical@14"
          ]
       },
       {
          "x":-1,
          "y":3,
          "z":2,
          "elements":[
             "xnet:netcable@1"
          ]
       },
       {
          "x":-1,
          "y":1,
          "z":1,
          "elements":[
             "xnet:netcable@1"
          ]
       },
       {
          "x":1,
          "y":3,
          "z":2,
          "elements":[
             "xnet:netcable@1"
          ]
       },
       {
          "x":0,
          "y":1,
          "z":1,
          "nbt":{
             "id":"overloaded:infinite_tank"
          },
          "elements":[
             "overloaded:infinite_tank@0"
          ]
       },
       {
          "x":2,
          "y":3,
          "z":2,
          "elements":[
             "appliedenergistics2:quartz_glass@0"
          ]
       },
       {
          "x":1,
          "y":1,
          "z":1,
          "elements":[
             "xnet:netcable@1"
          ]
       },
       {
          "x":2,
          "y":1,
          "z":1,
          "elements":[
             "chisel:technical@14"
          ]
       },
       {
          "x":-2,
          "y":4,
          "z":2,
          "elements":[
             "modularmachinery:blockcasing@0"
          ]
       },
       {
          "x":-2,
          "y":2,
          "z":1,
          "elements":[
             "chisel:technical@14"
          ]
       },
       {
          "x":-1,
          "y":4,
          "z":2,
          "elements":[
             "appliedenergistics2:quartz_glass@0"
          ]
       },
       {
          "x":0,
          "y":4,
          "z":2,
          "elements":[
             "appliedenergistics2:quartz_glass@0"
          ]
       },
       {
          "x":-1,
          "y":2,
          "z":1,
          "elements":[
             "xnet:netcable@1"
          ]
       },
       {
          "x":1,
          "y":4,
          "z":2,
          "elements":[
             "appliedenergistics2:quartz_glass@0"
          ]
       }
    ]
 }