{
    "registryname":"orematic5000",
    "localizedname":"OreMatic 5000",
    "color":"AAB4BA",
    "parts":[
       {
          "x":1,
          "y":2,
          "z":1,
          "elements":[
             "appliedenergistics2:quartz_glass@0"
          ]
       },
       {
          "x":-1,
          "y":0,
          "z":0,
          "elements":[
             "modularmachinery:blockcasing@0"
          ]
       },
       {
          "x":-1,
          "y":0,
          "z":1,
          "elements":[
             "modularmachinery:blockoutputbus"
          ]
       },
       {
          "x":0,
          "y":2,
          "z":2,
          "elements":[
             "appliedenergistics2:quartz_glass@0"
          ]
       },
       {
          "x":1,
          "y":2,
          "z":2,
          "elements":[
             "modularmachinery:blockcasing@0"
          ]
       },
       {
          "x":1,
          "y":0,
          "z":0,
          "elements":[
             "modularmachinery:blockcasing@0"
          ]
       },
       {
          "x":-1,
          "y":0,
          "z":2,
          "elements":[
             "modularmachinery:blockcasing@0"
          ]
       },
       {
          "x":0,
          "y":0,
          "z":1,
          "elements":[
             "modularmachinery:blockcasing@0"
          ]
       },
       {
          "x":1,
          "y":0,
          "z":1,
          "elements":[
             "modularmachinery:blockinputbus"
          ]
       },
       {
          "x":0,
          "y":0,
          "z":2,
          "elements":[
             "modularmachinery:blockenergyinputhatch"
          ]
       },
       {
          "x":1,
          "y":0,
          "z":2,
          "elements":[
             "modularmachinery:blockcasing@0"
          ]
       },
       {
          "x":-1,
          "y":3,
          "z":0,
          "elements":[
             "modularmachinery:blockcasing@0"
          ]
       },
       {
          "x":0,
          "y":3,
          "z":0,
          "elements":[
             "modularmachinery:blockcasing@0"
          ]
       },
       {
          "x":-1,
          "y":3,
          "z":1,
          "elements":[
             "modularmachinery:blockcasing@0"
          ]
       },
       {
          "x":1,
          "y":3,
          "z":0,
          "elements":[
             "modularmachinery:blockcasing@0"
          ]
       },
       {
          "x":-1,
          "y":1,
          "z":0,
          "elements":[
             "modularmachinery:blockcasing@0"
          ]
       },
       {
          "x":-1,
          "y":3,
          "z":2,
          "elements":[
             "modularmachinery:blockcasing@0"
          ]
       },
       {
          "x":0,
          "y":3,
          "z":1,
          "elements":[
             "appliedenergistics2:quartz_glass@0"
          ]
       },
       {
          "x":0,
          "y":1,
          "z":0,
          "elements":[
             "appliedenergistics2:quartz_glass@0"
          ]
       },
       {
          "x":-1,
          "y":1,
          "z":1,
          "elements":[
             "appliedenergistics2:quartz_glass@0"
          ]
       },
       {
          "x":1,
          "y":3,
          "z":1,
          "elements":[
             "modularmachinery:blockcasing@0"
          ]
       },
       {
          "x":0,
          "y":3,
          "z":2,
          "elements":[
             "modularmachinery:blockcasing@0"
          ]
       },
       {
          "x":0,
          "y":1,
          "z":1,
          "elements":[
             "mekanism:machineblock@3"
          ]
       },
       {
          "x":1,
          "y":3,
          "z":2,
          "elements":[
             "modularmachinery:blockcasing@0"
          ]
       },
       {
          "x":1,
          "y":1,
          "z":0,
          "elements":[
             "modularmachinery:blockfluidinputhatch"
          ]
       },
       {
          "x":-1,
          "y":1,
          "z":2,
          "elements":[
             "modularmachinery:blockcasing@0"
          ]
       },
       {
          "x":1,
          "y":1,
          "z":1,
          "elements":[
             "appliedenergistics2:quartz_glass@0"
          ]
       },
       {
          "x":0,
          "y":1,
          "z":2,
          "elements":[
             "appliedenergistics2:quartz_glass@0"
          ]
       },
       {
          "x":1,
          "y":1,
          "z":2,
          "elements":[
             "modularmachinery:blockfluidinputhatch"
          ]
       },
       {
          "x":-1,
          "y":2,
          "z":0,
          "elements":[
             "modularmachinery:blockcasing@0"
          ]
       },
       {
          "x":0,
          "y":2,
          "z":0,
          "elements":[
             "appliedenergistics2:quartz_glass@0"
          ]
       },
       {
          "x":-1,
          "y":2,
          "z":1,
          "elements":[
             "appliedenergistics2:quartz_glass@0"
          ]
       },
       {
          "x":0,
          "y":2,
          "z":1,
          "elements":[
             "enderutilities:machine_0@0"
          ]
       },
       {
          "x":1,
          "y":2,
          "z":0,
          "elements":[
             "modularmachinery:blockfluidinputhatch"
          ]
       },
       {
          "x":-1,
          "y":2,
          "z":2,
          "elements":[
             "modularmachinery:blockcasing@0"
          ]
       }
    ]
 }